<?xml version="1.0" encoding="utf-8"?>
<!-- This URDF was automatically created by SolidWorks to URDF Exporter! Originally created by Stephen Brawner (brawner@gmail.com) 
     Commit Version: 1.6.0-4-g7f85cfe  Build Version: 1.6.7995.38578
     For more information, please see http://wiki.ros.org/sw_urdf_exporter -->
<robot
  name="dreambo_bipedal">
  <link
    name="base_link">
    <inertial>
      <origin
        xyz="0.00319845379693415 2.19411732916425E-05 0.0256245373852634"
        rpy="0 0 0" />
      <mass
        value="1.81891933891081" />
      <inertia
        ixx="0.00437409246405585"
        ixy="-1.95087868555913E-07"
        ixz="2.02434314123507E-05"
        iyy="0.00475106555542052"
        iyz="8.39800379193804E-08"
        izz="0.00752813235097887" />
    </inertial>
    <visual>
      <origin
        xyz="0 0 0"
        rpy="0 0 0" />
      <geometry>
        <mesh
          filename="package://dreambo_bipedal/meshes/base_link.STL" />
      </geometry>
      <material
        name="">
        <color
          rgba="1 1 1 1" />
      </material>
    </visual>
    <collision>
      <origin
        xyz="0 0 0"
        rpy="0 0 0" />
      <geometry>
        <mesh
          filename="package://dreambo_bipedal/meshes/base_link.STL" />
      </geometry>
    </collision>
  </link>
  <link
    name="imu_link">
    <inertial>
      <origin
        xyz="0 1.86618298939067E-17 -0.000799999999999997"
        rpy="0 0 0" />
      <mass
        value="0.00212391079934123" />
      <inertia
        ixx="3.26232590285566E-07"
        ixy="4.81830100010621E-23"
        ixz="7.338999136402E-25"
        iyy="1.72719563958009E-07"
        iyz="3.56565129159897E-25"
        izz="4.98045952302523E-07" />
    </inertial>
    <visual>
      <origin
        xyz="0 0 0"
        rpy="0 0 0" />
      <geometry>
        <mesh
          filename="package://dreambo_bipedal/meshes/imu_link.STL" />
      </geometry>
      <material
        name="">
        <color
          rgba="0.894117647058823 0.894117647058823 0.894117647058823 1" />
      </material>
    </visual>
    <collision>
      <origin
        xyz="0 0 0"
        rpy="0 0 0" />
      <geometry>
        <mesh
          filename="package://dreambo_bipedal/meshes/imu_link.STL" />
      </geometry>
    </collision>
  </link>
  <joint
    name="imu_joint"
    type="fixed">
    <origin
      xyz="-0.0960317112278797 -0.000118214044089267 0.0106"
      rpy="0 0 0" />
    <parent
      link="base_link" />
    <child
      link="imu_link" />
    <axis
      xyz="0 0 0" />
  </joint>
  <link
    name="l_hip_yaw_link">
    <inertial>
      <origin
        xyz="-0.0777031232773881 2.34971863497524E-05 -0.0610436536238089"
        rpy="0 0 0" />
      <mass
        value="1.01878467702785" />
      <inertia
        ixx="0.00123431443237392"
        ixy="7.70869582026842E-07"
        ixz="-3.003885763377E-05"
        iyy="0.000824720440306758"
        iyz="-5.95664103169516E-07"
        izz="0.000897264214524009" />
    </inertial>
    <visual>
      <origin
        xyz="0 0 0"
        rpy="0 0 0" />
      <geometry>
        <mesh
          filename="package://dreambo_bipedal/meshes/l_hip_yaw_link.STL" />
      </geometry>
      <material
        name="">
        <color
          rgba="0.894117647058823 0.894117647058823 0.894117647058823 1" />
      </material>
    </visual>
    <collision>
      <origin
        xyz="0 0 0"
        rpy="0 0 0" />
      <geometry>
        <mesh
          filename="package://dreambo_bipedal/meshes/l_hip_yaw_link.STL" />
      </geometry>
    </collision>
  </link>
  <joint
    name="l_hip_yaw_joint"
    type="revolute">
    <origin
      xyz="0 0.07 -0.006"
      rpy="0 0 0" />
    <parent
      link="base_link" />
    <child
      link="l_hip_yaw_link" />
    <axis
      xyz="0 0 1" />
    <limit
      lower="-0.2"
      upper="0.2"
      effort="17"
      velocity="42" />
  </joint>
  <link
    name="l_hip_roll_link">
    <inertial>
      <origin
        xyz="0.0551612580319456 -0.00194686189481211 2.57266092415637E-05"
        rpy="0 0 0" />
      <mass
        value="0.931054269669199" />
      <inertia
        ixx="0.000681553814914373"
        ixy="-3.06598003202241E-07"
        ixz="-5.95747572017175E-07"
        iyy="0.0011791018936461"
        iyz="7.71615389730672E-07"
        izz="0.000636573963711595" />
    </inertial>
    <visual>
      <origin
        xyz="0 0 0"
        rpy="0 0 0" />
      <geometry>
        <mesh
          filename="package://dreambo_bipedal/meshes/l_hip_roll_link.STL" />
      </geometry>
      <material
        name="">
        <color
          rgba="0.894117647058823 0.894117647058823 0.894117647058823 1" />
      </material>
    </visual>
    <collision>
      <origin
        xyz="0 0 0"
        rpy="0 0 0" />
      <geometry>
        <mesh
          filename="package://dreambo_bipedal/meshes/l_hip_roll_link.STL" />
      </geometry>
    </collision>
  </link>
  <joint
    name="l_hip_roll_joint"
    type="revolute">
    <origin
      xyz="-0.057917 0 -0.068"
      rpy="0 0 0" />
    <parent
      link="l_hip_yaw_link" />
    <child
      link="l_hip_roll_link" />
    <axis
      xyz="-1 0 0" />
    <limit
      lower="-0.2"
      upper="0.2"
      effort="60"
      velocity="20" />
    <dynamics
      damping="10"
      friction="100" />
  </joint>
  <link
    name="l_hip_pitch_link">
    <inertial>
      <origin
        xyz="-2.40962577582188E-15 0.00521081104756992 -0.0336612637634136"
        rpy="0 0 0" />
      <mass
        value="0.0910464422547246" />
      <inertia
        ixx="0.000132936503129587"
        ixy="-2.94698605029266E-21"
        ixz="-4.01365940663399E-20"
        iyy="0.000161715715361343"
        iyz="-1.12807737148567E-06"
        izz="3.09291224719929E-05" />
    </inertial>
    <visual>
      <origin
        xyz="0 0 0"
        rpy="0 0 0" />
      <geometry>
        <mesh
          filename="package://dreambo_bipedal/meshes/l_hip_pitch_link.STL" />
      </geometry>
      <material
        name="">
        <color
          rgba="0.894117647058823 0.894117647058823 0.894117647058823 1" />
      </material>
    </visual>
    <collision>
      <origin
        xyz="0 0 0"
        rpy="0 0 0" />
      <geometry>
        <mesh
          filename="package://dreambo_bipedal/meshes/l_hip_pitch_link.STL" />
      </geometry>
    </collision>
  </link>
  <joint
    name="l_hip_pitch_joint"
    type="revolute">
    <origin
      xyz="0.05781 0.02155 0"
      rpy="0 0 0" />
    <parent
      link="l_hip_roll_link" />
    <child
      link="l_hip_pitch_link" />
    <axis
      xyz="0 -1 0" />
    <limit
      lower="0"
      upper="1.2"
      effort="60"
      velocity="20" />
    <dynamics
      damping="10"
      friction="100" />
  </joint>
  <link
    name="l_knee_pitch_link">
    <inertial>
      <origin
        xyz="-2.46560753214226E-05 0.0225336680923507 -0.00480645108618877"
        rpy="0 0 0" />
      <mass
        value="0.971490392039293" />
      <inertia
        ixx="0.000686362716275165"
        ixy="7.71628164415011E-07"
        ixz="-5.95747350255229E-07"
        iyy="0.0012579114435512"
        iyz="-1.0995372219632E-05"
        izz="0.000721306554594231" />
    </inertial>
    <visual>
      <origin
        xyz="0 0 0"
        rpy="0 0 0" />
      <geometry>
        <mesh
          filename="package://dreambo_bipedal/meshes/l_knee_pitch_link.STL" />
      </geometry>
      <material
        name="">
        <color
          rgba="0.894117647058823 0.894117647058823 0.894117647058823 1" />
      </material>
    </visual>
    <collision>
      <origin
        xyz="0 0 0"
        rpy="0 0 0" />
      <geometry>
        <mesh
          filename="package://dreambo_bipedal/meshes/l_knee_pitch_link.STL" />
      </geometry>
    </collision>
  </link>
  <joint
    name="l_knee_pitch_joint"
    type="revolute">
    <origin
      xyz="0 0.012 -0.08"
      rpy="0 0 0" />
    <parent
      link="l_hip_pitch_link" />
    <child
      link="l_knee_pitch_link" />
    <axis
      xyz="0 1 0" />
    <limit
      lower="0"
      upper="1.2"
      effort="60"
      velocity="20" />
  </joint>
  <link
    name="l_ankle_pitch_link">
    <inertial>
      <origin
        xyz="0.0111488189615353 -0.00983003625620883 -0.0357477688589793"
        rpy="0 0 0" />
      <mass
        value="0.68752007748517" />
      <inertia
        ixx="0.000356241183646846"
        ixy="1.43176277419376E-07"
        ixz="5.63051040251881E-08"
        iyy="0.000353563503200877"
        iyz="-1.09360342269082E-06"
        izz="0.000286291213397041" />
    </inertial>
    <visual>
      <origin
        xyz="0 0 0"
        rpy="0 0 0" />
      <geometry>
        <mesh
          filename="package://dreambo_bipedal/meshes/l_ankle_pitch_link.STL" />
      </geometry>
      <material
        name="">
        <color
          rgba="0.894117647058823 0.894117647058823 0.894117647058823 1" />
      </material>
    </visual>
    <collision>
      <origin
        xyz="0 0 0"
        rpy="0 0 0" />
      <geometry>
        <mesh
          filename="package://dreambo_bipedal/meshes/l_ankle_pitch_link.STL" />
      </geometry>
    </collision>
  </link>
  <joint
    name="l_ankle_pitch_joint"
    type="revolute">
    <origin
      xyz="0 -0.0115 -0.09"
      rpy="0 0 0" />
    <parent
      link="l_knee_pitch_link" />
    <child
      link="l_ankle_pitch_link" />
    <axis
      xyz="0 -1 0" />
    <limit
      lower="0"
      upper="1.05"
      effort="14"
      velocity="37" />
  </joint>
  <link
    name="l_ankle_roll_link">
    <inertial>
      <origin
        xyz="-0.00312458693029689 1.32188174004066E-07 -0.0214290747398843"
        rpy="0 0 0" />
      <mass
        value="0.258324154754465" />
      <inertia
        ixx="0.0003388091838953"
        ixy="5.75586669125935E-09"
        ixz="1.31522366323702E-06"
        iyy="0.000365133101026928"
        iyz="1.16626083273434E-09"
        izz="0.000591788066152757" />
    </inertial>
    <visual>
      <origin
        xyz="0 0 0"
        rpy="0 0 0" />
      <geometry>
        <mesh
          filename="package://dreambo_bipedal/meshes/l_ankle_roll_link.STL" />
      </geometry>
      <material
        name="">
        <color
          rgba="0.894117647058823 0.894117647058823 0.894117647058823 1" />
      </material>
    </visual>
    <collision>
      <origin
        xyz="0 0 0"
        rpy="0 0 0" />
      <geometry>
        <mesh
          filename="package://dreambo_bipedal/meshes/l_ankle_roll_link.STL" />
      </geometry>
    </collision>
  </link>
  <joint
    name="l_ankle_roll_joint"
    type="revolute">
    <origin
      xyz="0.0011 0.0016 -0.070755"
      rpy="0 0 0" />
    <parent
      link="l_ankle_pitch_link" />
    <child
      link="l_ankle_roll_link" />
    <axis
      xyz="1 0 0" />
    <limit
      lower="-0.26"
      upper="0.2"
      effort="14"
      velocity="37" />
  </joint>
  <link
    name="r_hip_yaw_link">
    <inertial>
      <origin
        xyz="0.0777031221067374 -2.35025820187335E-05 -0.0610436592480709"
        rpy="0 0 0" />
      <mass
        value="1.01878451978028" />
      <inertia
        ixx="0.00123431432962355"
        ixy="7.71061087781223E-07"
        ixz="3.00388178855561E-05"
        iyy="0.000824720245697182"
        iyz="5.95638022445652E-07"
        izz="0.000897263932102722" />
    </inertial>
    <visual>
      <origin
        xyz="0 0 0"
        rpy="0 0 0" />
      <geometry>
        <mesh
          filename="package://dreambo_bipedal/meshes/r_hip_yaw_link.STL" />
      </geometry>
      <material
        name="">
        <color
          rgba="0.894117647058823 0.894117647058823 0.894117647058823 1" />
      </material>
    </visual>
    <collision>
      <origin
        xyz="0 0 0"
        rpy="0 0 0" />
      <geometry>
        <mesh
          filename="package://dreambo_bipedal/meshes/r_hip_yaw_link.STL" />
      </geometry>
    </collision>
  </link>
  <joint
    name="r_hip_yaw_joint"
    type="revolute">
    <origin
      xyz="0 -0.07 -0.006"
      rpy="0 0 0" />
    <parent
      link="base_link" />
    <child
      link="r_hip_yaw_link" />
    <axis
      xyz="0 0 1" />
    <limit
      lower="-0.2"
      upper="0.2"
      effort="17"
      velocity="42" />
  </joint>
  <link
    name="r_hip_roll_link">
    <inertial>
      <origin
        xyz="-0.0551612580319456 0.00194686189481207 2.57266092415637E-05"
        rpy="0 0 0" />
      <mass
        value="0.9310542696692" />
      <inertia
        ixx="0.000681553814914374"
        ixy="-3.06598003202629E-07"
        ixz="5.95747572017122E-07"
        iyy="0.0011791018936461"
        iyz="-7.71615389730791E-07"
        izz="0.000636573963711596" />
    </inertial>
    <visual>
      <origin
        xyz="0 0 0"
        rpy="0 0 0" />
      <geometry>
        <mesh
          filename="package://dreambo_bipedal/meshes/r_hip_roll_link.STL" />
      </geometry>
      <material
        name="">
        <color
          rgba="0.894117647058823 0.894117647058823 0.894117647058823 1" />
      </material>
    </visual>
    <collision>
      <origin
        xyz="0 0 0"
        rpy="0 0 0" />
      <geometry>
        <mesh
          filename="package://dreambo_bipedal/meshes/r_hip_roll_link.STL" />
      </geometry>
    </collision>
  </link>
  <joint
    name="r_hip_roll_joint"
    type="revolute">
    <origin
      xyz="0.0579166462453084 0 -0.0679999999999469"
      rpy="0 0 0" />
    <parent
      link="r_hip_yaw_link" />
    <child
      link="r_hip_roll_link" />
    <axis
      xyz="-1 0 0" />
    <limit
      lower="-0.2"
      upper="0.2"
      effort="60"
      velocity="20" />
    <dynamics
      damping="10"
      friction="100" />
  </joint>
  <link
    name="r_hip_pitch_link">
    <inertial>
      <origin
        xyz="2.38951382552227E-15 -0.00521081104756993 -0.0336612637634136"
        rpy="0 0 0" />
      <mass
        value="0.0910464422547247" />
      <inertia
        ixx="0.000132936503129587"
        ixy="-3.52023784690971E-20"
        ixz="-3.20069405090592E-20"
        iyy="0.000161715715361343"
        iyz="1.12807737148556E-06"
        izz="3.0929122471993E-05" />
    </inertial>
    <visual>
      <origin
        xyz="0 0 0"
        rpy="0 0 0" />
      <geometry>
        <mesh
          filename="package://dreambo_bipedal/meshes/r_hip_pitch_link.STL" />
      </geometry>
      <material
        name="">
        <color
          rgba="0.894117647058823 0.894117647058823 0.894117647058823 1" />
      </material>
    </visual>
    <collision>
      <origin
        xyz="0 0 0"
        rpy="0 0 0" />
      <geometry>
        <mesh
          filename="package://dreambo_bipedal/meshes/r_hip_pitch_link.STL" />
      </geometry>
    </collision>
  </link>
  <joint
    name="r_hip_pitch_joint"
    type="revolute">
    <origin
      xyz="-0.05781 -0.02155 0"
      rpy="0 0 0" />
    <parent
      link="r_hip_roll_link" />
    <child
      link="r_hip_pitch_link" />
    <axis
      xyz="0 -1 0" />
    <limit
      lower="-1.2"
      upper="0"
      effort="60"
      velocity="20" />
    <dynamics
      damping="10"
      friction="100" />
  </joint>
  <link
    name="r_knee_pitch_link">
    <inertial>
      <origin
        xyz="2.46560753214548E-05 -0.0225336680923506 -0.00480645108618877"
        rpy="0 0 0" />
      <mass
        value="0.971490392039294" />
      <inertia
        ixx="0.000686362716275166"
        ixy="7.71628164414669E-07"
        ixz="5.95747350255151E-07"
        iyy="0.0012579114435512"
        iyz="1.09953722196317E-05"
        izz="0.000721306554594232" />
    </inertial>
    <visual>
      <origin
        xyz="0 0 0"
        rpy="0 0 0" />
      <geometry>
        <mesh
          filename="package://dreambo_bipedal/meshes/r_knee_pitch_link.STL" />
      </geometry>
      <material
        name="">
        <color
          rgba="0.894117647058823 0.894117647058823 0.894117647058823 1" />
      </material>
    </visual>
    <collision>
      <origin
        xyz="0 0 0"
        rpy="0 0 0" />
      <geometry>
        <mesh
          filename="package://dreambo_bipedal/meshes/r_knee_pitch_link.STL" />
      </geometry>
    </collision>
  </link>
  <joint
    name="r_knee_pitch_joint"
    type="revolute">
    <origin
      xyz="0 -0.012 -0.08"
      rpy="0 0 0" />
    <parent
      link="r_hip_pitch_link" />
    <child
      link="r_knee_pitch_link" />
    <axis
      xyz="0 1 0" />
    <limit
      lower="-1.2"
      upper="0"
      effort="60"
      velocity="20" />
  </joint>
  <link
    name="r_ankle_pitch_link">
    <inertial>
      <origin
        xyz="-0.0111488189615353 0.0098300362562088 -0.0357477688589794"
        rpy="0 0 0" />
      <mass
        value="0.68752007748517" />
      <inertia
        ixx="0.000356241183646846"
        ixy="1.43176277419384E-07"
        ixz="-5.63051040250956E-08"
        iyy="0.000353563503200878"
        iyz="1.0936034226907E-06"
        izz="0.00028629121339704" />
    </inertial>
    <visual>
      <origin
        xyz="0 0 0"
        rpy="0 0 0" />
      <geometry>
        <mesh
          filename="package://dreambo_bipedal/meshes/r_ankle_pitch_link.STL" />
      </geometry>
      <material
        name="">
        <color
          rgba="0.894117647058823 0.894117647058823 0.894117647058823 1" />
      </material>
    </visual>
    <collision>
      <origin
        xyz="0 0 0"
        rpy="0 0 0" />
      <geometry>
        <mesh
          filename="package://dreambo_bipedal/meshes/r_ankle_pitch_link.STL" />
      </geometry>
    </collision>
  </link>
  <joint
    name="r_ankle_pitch_joint"
    type="revolute">
    <origin
      xyz="0 0.0115 -0.09"
      rpy="0 0 0" />
    <parent
      link="r_knee_pitch_link" />
    <child
      link="r_ankle_pitch_link" />
    <axis
      xyz="0 1 0" />
    <limit
      lower="0"
      upper="1.05"
      effort="14"
      velocity="37" />
  </joint>
  <link
    name="r_ankle_roll_link">
    <inertial>
      <origin
        xyz="0.00312458676414318 -1.32095841431923E-07 -0.0214290747509172"
        rpy="0 0 0" />
      <mass
        value="0.258324154865949" />
      <inertia
        ixx="0.000338809185527952"
        ixy="5.75840835746602E-09"
        ixz="-1.31522357459993E-06"
        iyy="0.000365133100610587"
        iyz="-1.16641865483339E-09"
        izz="0.00059178806739296" />
    </inertial>
    <visual>
      <origin
        xyz="0 0 0"
        rpy="0 0 0" />
      <geometry>
        <mesh
          filename="package://dreambo_bipedal/meshes/r_ankle_roll_link.STL" />
      </geometry>
      <material
        name="">
        <color
          rgba="0.894117647058823 0.894117647058823 0.894117647058823 1" />
      </material>
    </visual>
    <collision>
      <origin
        xyz="0 0 0"
        rpy="0 0 0" />
      <geometry>
        <mesh
          filename="package://dreambo_bipedal/meshes/r_ankle_roll_link.STL" />
      </geometry>
    </collision>
  </link>
  <joint
    name="r_ankle_roll_joint"
    type="revolute">
    <origin
      xyz="-0.0011 -0.0016 -0.070755"
      rpy="0 0 0" />
    <parent
      link="r_ankle_pitch_link" />
    <child
      link="r_ankle_roll_link" />
    <axis
      xyz="-1 0 0" />
    <limit
      lower="-0.2"
      upper="0.26"
      effort="14"
      velocity="37" />
  </joint>
</robot>