<?xml version="1.0" encoding="utf-8"?>
<robot name="dreambo_bipedal">
  <link name="base_link">
    <inertial>
      <origin xyz="0.00319845379693415 2.19411732916425E-05 0.0256245373852634" rpy="0 0 0" />
      <mass value="1.81891933891081" />
      <inertia ixx="0.00437409246405585" ixy="-1.95087868555934E-07" ixz="2.02434314123506E-05" iyy="0.00475106555542052" iyz="8.39800379193748E-08" izz="0.00752813235097887" />
    </inertial>
    <visual>
      <origin xyz="0 0 0" rpy="0 0 0" />
      <geometry>
        <mesh filename="package://dreambo_bipedal/meshes/base_link.STL" />
      </geometry>
      <material name="">
        <color rgba="1 1 1 1" />
      </material>
    </visual>
    <collision>
      <origin xyz="0 0 0" rpy="0 0 0" />
      <geometry>
        <mesh filename="package://dreambo_bipedal/meshes/base_link.STL" />
      </geometry>
    </collision>
  </link>
  <link name="imu_link">
    <inertial>
      <origin xyz="0 1.76860479386698E-17 -0.000799999999999997" rpy="0 0 0" />
      <mass value="0.00212391079934123" />
      <inertia ixx="3.26232590285566E-07" ixy="4.11078632285966E-23" ixz="-2.61967307192194E-25" iyy="1.72719563958009E-07" iyz="-6.76867533750972E-25" izz="4.98045952302523E-07" />
    </inertial>
    <visual>
      <origin xyz="0 0 0" rpy="0 0 0" />
      <geometry>
        <mesh filename="package://dreambo_bipedal/meshes/imu_link.STL" />
      </geometry>
      <material name="">
        <color rgba="0.894117647058823 0.894117647058823 0.894117647058823 1" />
      </material>
    </visual>
    <collision>
      <origin xyz="0 0 0" rpy="0 0 0" />
      <geometry>
        <mesh filename="package://dreambo_bipedal/meshes/imu_link.STL" />
      </geometry>
    </collision>
  </link>
  <joint name="imu_joint" type="fixed">
    <origin xyz="-0.0960317112278797 -0.000118214044089267 0.0106" rpy="0 0 0" />
    <parent link="base_link" />
    <child link="imu_link" />
    <axis xyz="0 0 0" />
  </joint>
  <link name="l_hip_yaw_link">
    <inertial>
      <origin xyz="-0.0777031232773881 2.34971863497802E-05 -0.0610436536238089" rpy="0 0 0" />
      <mass value="1.01878467702785" />
      <inertia ixx="0.00123431443237392" ixy="7.70869582026747E-07" ixz="-3.003885763377E-05" iyy="0.000824720440306758" iyz="-5.95664103169563E-07" izz="0.000897264214524008" />
    </inertial>
    <visual>
      <origin xyz="0 0 0" rpy="0 0 0" />
      <geometry>
        <mesh filename="package://dreambo_bipedal/meshes/l_hip_yaw_link.STL" />
      </geometry>
      <material name="">
        <color rgba="0.894117647058823 0.894117647058823 0.894117647058823 1" />
      </material>
    </visual>
    <collision>
      <origin xyz="0 0 0" rpy="0 0 0" />
      <geometry>
        <mesh filename="package://dreambo_bipedal/meshes/l_hip_yaw_link.STL" />
      </geometry>
    </collision>
  </link>
  <joint name="l_hip_yaw_joint" type="revolute">
    <origin xyz="0 0.07 -0.006" rpy="0 0 0" />
    <parent link="base_link" />
    <child link="l_hip_yaw_link" />
    <axis xyz="0 0 1" />
    <limit lower="-0.2" upper="0.2" effort="17" velocity="42" />
  </joint>
  <link name="l_hip_roll_link">
    <inertial>
      <origin xyz="0.0551612580319456 -0.00194686189481211 2.57266092415637E-05" rpy="0 0 0" />
      <mass value="0.931054269669199" />
      <inertia ixx="0.000681553814914373" ixy="-3.06598003202223E-07" ixz="-5.95747572017256E-07" iyy="0.0011791018936461" iyz="7.71615389730664E-07" izz="0.000636573963711595" />
    </inertial>
    <visual>
      <origin xyz="0 0 0" rpy="0 0 0" />
      <geometry>
        <mesh filename="package://dreambo_bipedal/meshes/l_hip_roll_link.STL" />
      </geometry>
      <material name="">
        <color rgba="0.894117647058823 0.894117647058823 0.894117647058823 1" />
      </material>
    </visual>
    <collision>
      <origin xyz="0 0 0" rpy="0 0 0" />
      <geometry>
        <mesh filename="package://dreambo_bipedal/meshes/l_hip_roll_link.STL" />
      </geometry>
    </collision>
  </link>
  <joint name="l_hip_roll_joint" type="revolute">
    <origin xyz="-0.057917 0 -0.068" rpy="0 0 0" />
    <parent link="l_hip_yaw_link" />
    <child link="l_hip_roll_link" />
    <axis xyz="-1 0 0" />
    <limit lower="-0.2" upper="0.2" effort="60" velocity="20" />
    <dynamics damping="10" friction="100" />
  </joint>
  <link name="l_hip_pitch_link">
    <inertial>
      <origin xyz="-2.41264798937768E-15 0.00521081104756992 -0.0336612637634136" rpy="0 0 0" />
      <mass value="0.0910464422547246" />
      <inertia ixx="0.000132936503129587" ixy="-3.36359831338186E-21" ixz="-4.1895011121913E-20" iyy="0.000161715715361343" iyz="-1.12807737148567E-06" izz="3.09291224719929E-05" />
    </inertial>
    <visual>
      <origin xyz="0 0 0" rpy="0 0 0" />
      <geometry>
        <mesh filename="package://dreambo_bipedal/meshes/l_hip_pitch_link.STL" />
      </geometry>
      <material name="">
        <color rgba="0.894117647058823 0.894117647058823 0.894117647058823 1" />
      </material>
    </visual>
    <collision>
      <origin xyz="0 0 0" rpy="0 0 0" />
      <geometry>
        <mesh filename="package://dreambo_bipedal/meshes/l_hip_pitch_link.STL" />
      </geometry>
    </collision>
  </link>
  <joint name="l_hip_pitch_joint" type="revolute">
    <origin xyz="0.05781 0.02155 0" rpy="0 0 0" />
    <parent link="l_hip_roll_link" />
    <child link="l_hip_pitch_link" />
    <axis xyz="0 -1 0" />
    <limit lower="-0.1" upper="1.7" effort="60" velocity="20" />
    <dynamics damping="10" friction="100" />
  </joint>
  <link name="l_knee_pitch_link">
    <inertial>
      <origin xyz="-2.4656075319031E-05 0.0225336680923506 -0.00480645108618838" rpy="0 0 0" />
      <mass value="0.971490392039293" />
      <inertia ixx="0.000686362716275165" ixy="7.71628164414981E-07" ixz="-5.95747350255148E-07" iyy="0.0012579114435512" iyz="-1.09953722196319E-05" izz="0.000721306554594231" />
    </inertial>
    <visual>
      <origin xyz="0 0 0" rpy="0 0 0" />
      <geometry>
        <mesh filename="package://dreambo_bipedal/meshes/l_knee_pitch_link.STL" />
      </geometry>
      <material name="">
        <color rgba="0.894117647058823 0.894117647058823 0.894117647058823 1" />
      </material>
    </visual>
    <collision>
      <origin xyz="0 0 0" rpy="0 0 0" />
      <geometry>
        <mesh filename="package://dreambo_bipedal/meshes/l_knee_pitch_link.STL" />
      </geometry>
    </collision>
  </link>
  <joint name="l_knee_pitch_joint" type="revolute">
    <origin xyz="0 0.012 -0.08" rpy="0 0 0" />
    <parent link="l_hip_pitch_link" />
    <child link="l_knee_pitch_link" />
    <axis xyz="0 1 0" />
    <limit lower="-0.1" upper="2.2" effort="60" velocity="20" />
  </joint>
  <link name="l_ankle_pitch_link">
    <inertial>
      <origin xyz="0.0111488189615353 -0.00983003625620882 -0.0357477688589794" rpy="0 0 0" />
      <mass value="0.68752007748517" />
      <inertia ixx="0.000356241183646846" ixy="1.43176277419375E-07" ixz="5.63051040251851E-08" iyy="0.000353563503200878" iyz="-1.09360342269081E-06" izz="0.000286291213397041" />
    </inertial>
    <visual>
      <origin xyz="0 0 0" rpy="0 0 0" />
      <geometry>
        <mesh filename="package://dreambo_bipedal/meshes/l_ankle_pitch_link.STL" />
      </geometry>
      <material name="">
        <color rgba="0.894117647058823 0.894117647058823 0.894117647058823 1" />
      </material>
    </visual>
    <collision>
      <origin xyz="0 0 0" rpy="0 0 0" />
      <geometry>
        <mesh filename="package://dreambo_bipedal/meshes/l_ankle_pitch_link.STL" />
      </geometry>
    </collision>
  </link>
  <joint name="l_ankle_pitch_joint" type="revolute">
    <origin xyz="0 -0.0115 -0.09" rpy="0 0 0" />
    <parent link="l_knee_pitch_link" />
    <child link="l_ankle_pitch_link" />
    <axis xyz="0 -1 0" />
    <limit lower="0" upper="1.05" effort="14" velocity="37" />
  </joint>
  <link name="l_ankle_roll_link">
    <inertial>
      <origin xyz="-0.00312458693029854 1.32188173629366E-07 -0.0214290747398834" rpy="0 0 0" />
      <mass value="0.258324154754455" />
      <inertia ixx="0.000338809183895299" ixy="5.75586669540759E-09" ixz="1.31522366323642E-06" iyy="0.000365133101026911" iyz="1.16626083259462E-09" izz="0.00059178806615274" />
    </inertial>
    <visual>
      <origin xyz="0 0 0" rpy="0 0 0" />
      <geometry>
        <mesh filename="package://dreambo_bipedal/meshes/l_ankle_roll_link.STL" />
      </geometry>
      <material name="">
        <color rgba="0.894117647058823 0.894117647058823 0.894117647058823 1" />
      </material>
    </visual>
    <collision>
      <origin xyz="0 0 0" rpy="0 0 0" />
      <geometry>
        <mesh filename="package://dreambo_bipedal/meshes/l_ankle_roll_link.STL" />
      </geometry>
    </collision>
  </link>
  <joint name="l_ankle_roll_joint" type="revolute">
    <origin xyz="0.0011 0.0016 -0.070755" rpy="0 0 0" />
    <parent link="l_ankle_pitch_link" />
    <child link="l_ankle_roll_link" />
    <axis xyz="1 0 0" />
    <limit lower="-0.2" upper="0.26" effort="14" velocity="37" />
  </joint>
  <link name="r_hip_yaw_link">
    <inertial>
      <origin xyz="-0.0777031221067375 2.35025820187751E-05 -0.061043659248071" rpy="0 0 0" />
      <mass value="1.01878451978028" />
      <inertia ixx="0.00123431432962355" ixy="7.71061087781195E-07" ixz="-3.00388178855561E-05" iyy="0.000824720245697182" iyz="-5.95638022445635E-07" izz="0.000897263932102722" />
    </inertial>
    <visual>
      <origin xyz="0 0 0" rpy="0 0 0" />
      <geometry>
        <mesh filename="package://dreambo_bipedal/meshes/r_hip_yaw_link.STL" />
      </geometry>
      <material name="">
        <color rgba="0.894117647058823 0.894117647058823 0.894117647058823 1" />
      </material>
    </visual>
    <collision>
      <origin xyz="0 0 0" rpy="0 0 0" />
      <geometry>
        <mesh filename="package://dreambo_bipedal/meshes/r_hip_yaw_link.STL" />
      </geometry>
    </collision>
  </link>
  <joint name="r_hip_yaw_joint" type="revolute">
    <origin xyz="0 -0.07 -0.006" rpy="0 0 -3.14159265358979" />
    <parent link="base_link" />
    <child link="r_hip_yaw_link" />
    <axis xyz="0 0 1" />
    <limit lower="-0.2" upper="0.2" effort="17" velocity="42" />
  </joint>
  <link name="r_hip_roll_link">
    <inertial>
      <origin xyz="0.0551612580319456 -0.00194686189481205 2.57266092415914E-05" rpy="0 0 0" />
      <mass value="0.9310542696692" />
      <inertia ixx="0.000681553814914374" ixy="-3.06598003202553E-07" ixz="-5.95747572017119E-07" iyy="0.0011791018936461" iyz="7.71615389730766E-07" izz="0.000636573963711596" />
    </inertial>
    <visual>
      <origin xyz="0 0 0" rpy="0 0 0" />
      <geometry>
        <mesh filename="package://dreambo_bipedal/meshes/r_hip_roll_link.STL" />
      </geometry>
      <material name="">
        <color rgba="0.894117647058823 0.894117647058823 0.894117647058823 1" />
      </material>
    </visual>
    <collision>
      <origin xyz="0 0 0" rpy="0 0 0" />
      <geometry>
        <mesh filename="package://dreambo_bipedal/meshes/r_hip_roll_link.STL" />
      </geometry>
    </collision>
  </link>
  <joint name="r_hip_roll_joint" type="revolute">
    <origin xyz="-0.057917 0 -0.068" rpy="0 0 0" />
    <parent link="r_hip_yaw_link" />
    <child link="r_hip_roll_link" />
    <axis xyz="-1 0 0" />
    <limit lower="-0.2" upper="0.2" effort="60" velocity="20" />
    <dynamics damping="10" friction="100" />
  </joint>
  <link name="r_hip_pitch_link">
    <inertial>
      <origin xyz="-2.38710147568849E-15 0.00521081104756992 -0.0336612637634136" rpy="0 0 0" />
      <mass value="0.0910464422547247" />
      <inertia ixx="0.000132936503129587" ixy="-3.77690233299114E-21" ixz="3.24426531539879E-20" iyy="0.000161715715361343" iyz="-1.12807737148557E-06" izz="3.0929122471993E-05" />
    </inertial>
    <visual>
      <origin xyz="0 0 0" rpy="0 0 0" />
      <geometry>
        <mesh filename="package://dreambo_bipedal/meshes/r_hip_pitch_link.STL" />
      </geometry>
      <material name="">
        <color rgba="0.894117647058823 0.894117647058823 0.894117647058823 1" />
      </material>
    </visual>
    <collision>
      <origin xyz="0 0 0" rpy="0 0 0" />
      <geometry>
        <mesh filename="package://dreambo_bipedal/meshes/r_hip_pitch_link.STL" />
      </geometry>
    </collision>
  </link>
  <joint name="r_hip_pitch_joint" type="revolute">
    <origin xyz="0.05781 0.02155 0" rpy="0 0 0" />
    <parent link="r_hip_roll_link" />
    <child link="r_hip_pitch_link" />
    <axis xyz="0 -1 0" />
    <limit lower="-0.1" upper="1.7" effort="60" velocity="20" />
    <dynamics damping="10" friction="100" />
  </joint>
  <link name="r_knee_pitch_link">
    <inertial>
      <origin xyz="-2.46560753190358E-05 0.0225336680923507 -0.00480645108618835" rpy="0 0 0" />
      <mass value="0.971490392039294" />
      <inertia ixx="0.000686362716275166" ixy="7.7162816441531E-07" ixz="-5.9574735025526E-07" iyy="0.0012579114435512" iyz="-1.09953722196314E-05" izz="0.000721306554594232" />
    </inertial>
    <visual>
      <origin xyz="0 0 0" rpy="0 0 0" />
      <geometry>
        <mesh filename="package://dreambo_bipedal/meshes/r_knee_pitch_link.STL" />
      </geometry>
      <material name="">
        <color rgba="0.894117647058823 0.894117647058823 0.894117647058823 1" />
      </material>
    </visual>
    <collision>
      <origin xyz="0 0 0" rpy="0 0 0" />
      <geometry>
        <mesh filename="package://dreambo_bipedal/meshes/r_knee_pitch_link.STL" />
      </geometry>
    </collision>
  </link>
  <joint name="r_knee_pitch_joint" type="revolute">
    <origin xyz="0 0.0119999999999999 -0.0800000000000005" rpy="0 0 0" />
    <parent link="r_hip_pitch_link" />
    <child link="r_knee_pitch_link" />
    <axis xyz="0 1 0" />
    <limit lower="-0.1" upper="2.2" effort="60" velocity="20" />
  </joint>
  <link name="r_ankle_pitch_link">
    <inertial>
      <origin xyz="-0.0111488189615353 -0.00983003625620882 0.0357477688589793" rpy="0 0 0" />
      <mass value="0.68752007748517" />
      <inertia ixx="0.000356241183646846" ixy="-1.43176277419382E-07" ixz="5.63051040251018E-08" iyy="0.000353563503200878" iyz="1.09360342269064E-06" izz="0.000286291213397041" />
    </inertial>
    <visual>
      <origin xyz="0 0 0" rpy="0 0 0" />
      <geometry>
        <mesh filename="package://dreambo_bipedal/meshes/r_ankle_pitch_link.STL" />
      </geometry>
      <material name="">
        <color rgba="0.894117647058823 0.894117647058823 0.894117647058823 1" />
      </material>
    </visual>
    <collision>
      <origin xyz="0 0 0" rpy="0 0 0" />
      <geometry>
        <mesh filename="package://dreambo_bipedal/meshes/r_ankle_pitch_link.STL" />
      </geometry>
    </collision>
  </link>
  <joint name="r_ankle_pitch_joint" type="revolute">
    <origin xyz="0 -0.0115 -0.0900000000001102" rpy="-3.14159265358979 0 3.14159265358979" />
    <parent link="r_knee_pitch_link" />
    <child link="r_ankle_pitch_link" />
    <axis xyz="0 -1 0" />
    <limit lower="0" upper="1.05" effort="14" velocity="37" />
  </joint>
  <link name="r_ankle_roll_link">
    <inertial>
      <origin xyz="0.00312458676414483 -1.32095841043345E-07 -0.0214290747509164" rpy="0 0 0" />
      <mass value="0.258324154865939" />
      <inertia ixx="0.000338809185527951" ixy="5.75840836163673E-09" ixz="-1.31522357459931E-06" iyy="0.00036513310061057" iyz="-1.1664186546501E-09" izz="0.000591788067392942" />
    </inertial>
    <visual>
      <origin xyz="0 0 0" rpy="0 0 0" />
      <geometry>
        <mesh filename="package://dreambo_bipedal/meshes/r_ankle_roll_link.STL" />
      </geometry>
      <material name="">
        <color rgba="0.894117647058823 0.894117647058823 0.894117647058823 1" />
      </material>
    </visual>
    <collision>
      <origin xyz="0 0 0" rpy="0 0 0" />
      <geometry>
        <mesh filename="package://dreambo_bipedal/meshes/r_ankle_roll_link.STL" />
      </geometry>
    </collision>
  </link>
  <joint name="r_ankle_roll_joint" type="revolute">
    <origin xyz="-0.00109999999999963 0.00160000000000105 0.0707548339959389" rpy="3.14159265358979 0 0" />
    <parent link="r_ankle_pitch_link" />
    <child link="r_ankle_roll_link" />
    <axis xyz="-1 0 0" />
    <limit lower="-0.2" upper="0.26" effort="14" velocity="37" />
  </joint>
</robot>